<?xml version="1.0" ?>
<sdf version="1.6">

  <model name="mooring">        
    
    <!-- Short Links   
    <include>
      <pose>0 0 0 0 0 0</pose>
      <uri>model://mooring_block</uri>
      <name>mooring_block</name>
    </include>

    <include>
      <pose>0.25 0 0.25 0 0 0</pose>
      <uri>model://chain</uri>
      <name>chain</name>
    </include>

    <include>
      <pose>10 0 0.5 0 0 0</pose>
      <uri>model://spherical_buoy</uri>
      <name>spherical_buoy</name>
    </include>

    <joint type="ball" name="block_chain_joint">
      <pose>-0.25 0 0 0 0 0</pose>
      <parent>mooring_block::base_link</parent>
      <child>chain::chain_link0::base_link</child>
    </joint>

    <joint type="ball" name="chain_buoy_link">
      <pose>0 0 -0.25 0 0 0</pose>
      <parent>chain::chain_link19::base_link</parent>
      <child>spherical_buoy::base_link</child>
    </joint> -->

    <!-- Long Links  -->
    <include>
      <pose>0 0 0 0 0 0</pose>
      <uri>model://mooring_block</uri>
      <name>mooring_block</name>
    </include>

    <include>
      <pose>2.5 0 0.25 0 0 0</pose>
      <uri>model://chain_long</uri>
      <name>chain</name>
    </include>

    <include>
      <pose>10 0 0.5 0 0 0</pose>
      <uri>model://spherical_buoy</uri>
      <name>spherical_buoy</name>
    </include>

    <joint type="ball" name="block_chain_joint">
      <pose>-2.5 0 0 0 0 0</pose>
      <parent>mooring_block::base_link</parent>
      <child>chain::chain_link0::base_link</child>
    </joint>

    <joint type="ball" name="chain_buoy_link">
      <pose>0 0 -0.25 0 0 0</pose>
      <parent>chain::chain_link1::base_link</parent>
      <child>spherical_buoy::base_link</child>
    </joint>

  </model>
</sdf>
