<?xml version='1.0'?>
<!--
  Copyright (C) 2019  Rhys Mainwaring

  This program is free software: you can redistribute it and/or modify
  it under the terms of the GNU General Public License as published by
  the Free Software Foundation, either version 3 of the License, or
  (at your option) any later version.

  This program is distributed in the hope that it will be useful,
  but WITHOUT ANY WARRANTY; without even the implied warranty of
  MERCHANTABILITY or FITNESS FOR A PARTICULAR PURPOSE.  See the
  GNU General Public License for more details.

  You should have received a copy of the GNU General Public License
  along with this program.  If not, see <https://www.gnu.org/licenses/>.
-->
<sdf version='1.6'>
  <model name='rs750'>
    <pose>0 0 0 0 0 0</pose>
    <static>false</static>

    <plugin name="link_joint_controller" filename="libLinkJointControllerPlugin.so">
      <input_topic>/cmd_vel</input_topic>
      <link_name>thruster_link</link_name>
      <link_scale>5</link_scale>
      <link_type>velocity</link_type>
      <link_pid>1000 0 10</link_pid>
      <joint_name>thruster_joint</joint_name>
      <joint_scale>0.8</joint_scale>
      <joint_type>position</joint_type>
      <joint_pid>1000 0 10</joint_pid>
    </plugin>

    <plugin name="hydrodynamics" filename="libHydrodynamicsPlugin.so">
      <!-- Wave Model -->
      <wave_model>ocean_waves</wave_model>

      <!-- Hydrodynamics -->
      <damping_on>true</damping_on>
      <viscous_drag_on>true</viscous_drag_on>
      <pressure_drag_on>true</pressure_drag_on>

      <!-- Linear and Angular Damping -->
      <cDampL1>1.0E-6</cDampL1>
      <cDampL2>1.0E-6</cDampL2>
      <cDampR1>1.0E-6</cDampR1>
      <cDampR2>1.0E-6</cDampR2>

      <!-- 'Pressure' Drag -->
      <cPDrag1>1.0E+2</cPDrag1>
      <cPDrag2>1.0E+2</cPDrag2>
      <fPDrag>0.4</fPDrag>
      <cSDrag1>1.0E+2</cSDrag1>
      <cSDrag2>1.0E+2</cSDrag2>
      <fSDrag>0.4</fSDrag>
      <vRDrag>1.0</vRDrag>

      <!-- Markers -->
      <markers>
        <update_rate>30</update_rate>
        <water_patch>false</water_patch>
        <waterline>false</waterline>
        <underwater_surface>false</underwater_surface>
      </markers>
    </plugin>

    <!-- Hull -->
    <link name="base_link">
      <visual name="hull_visual">
        <geometry>
          <mesh>
            <uri>model://rs750/meshes/rs750_hull_foils.stl</uri>
          </mesh>
        </geometry>
        <material>
          <script>
            <name>Gazebo/Red</name>
          </script>
        </material>
      </visual>
      <visual name="deck_visual">
        <geometry>
          <mesh>
            <uri>model://rs750/meshes/rs750_deck.stl</uri>
          </mesh>
        </geometry>
        <material>
          <script>
            <name>Gazebo/Gray</name>
          </script>
        </material>
      </visual>
      <collision name="base_collision">
        <geometry>
          <mesh>
            <uri>model://rs750/meshes/rs750_hull_collision_3.stl</uri>
          </mesh>
        </geometry>
      </collision>
      <inertial>
        <pose>-0.1 0 -0.75 0 0 0</pose>
        <mass>60</mass>
        <inertia>
          <ixx>10</ixx>
          <ixy>0</ixy>
          <iyy>50</iyy>
          <iyz>0</iyz>
          <izz>43</izz>
        </inertia>
      </inertial>

    </link>

    <!-- Thruster -->
    <link name="thruster_link">
      <pose>-1.25 0 -0.25 0 0 0</pose>
      <visual name="thruster_visual">
        <geometry>
          <box>
            <size>0.05 0.05 0.05</size>
          </box>
        </geometry>
        <material>
          <script>
            <name>Gazebo/Black</name>
          </script>
        </material>
      </visual>
      <collision name="thruster_collision">
        <geometry>
          <box>
            <size>0.05 0.05 0.05</size>
          </box>
        </geometry>
      </collision>
      <inertial>
        <pose>0 0 0 0 0 0</pose>
        <mass>0.1</mass>
        <inertia>
          <ixx>0.1</ixx>
          <ixy>0</ixy>
          <iyy>0.1</iyy>
          <iyz>0</iyz>
          <izz>0.1</izz>
        </inertia>
      </inertial>
    </link>

    <joint type="revolute" name="thruster_joint">
      <pose>0 0 0 0 0 0</pose>
      <child>thruster_link</child>
      <parent>base_link</parent>
      <axis>
        <xyz>0 0 1</xyz>
        <limit>
          <lower>-0.8</lower>
          <upper>0.8</upper>
        </limit>
      </axis>
    </joint>

  </model>
</sdf>
