<?xml version='1.0'?>
<!--
  Copyright (C) 2019  Rhys Mainwaring

  This program is free software: you can redistribute it and/or modify
  it under the terms of the GNU General Public License as published by
  the Free Software Foundation, either version 3 of the License, or
  (at your option) any later version.

  This program is distributed in the hope that it will be useful,
  but WITHOUT ANY WARRANTY; without even the implied warranty of
  MERCHANTABILITY or FITNESS FOR A PARTICULAR PURPOSE.  See the
  GNU General Public License for more details.

  You should have received a copy of the GNU General Public License
  along with this program.  If not, see <https://www.gnu.org/licenses/>.
-->
<sdf version='1.6'>
  <model name='rs750'>
    <pose>0 0 0 0 0 0</pose>
    <static>false</static>
    <enable_wind>true</enable_wind>

    <!-- Controllers -->
    <plugin name="rudder_controller" filename="libLinkJointControllerPlugin.so">
      <input_topic>/cmd_vel</input_topic>
      <link_name>__default__</link_name>
      <link_scale>0</link_scale>
      <link_type>velocity</link_type>
      <link_pid>1000 0 10</link_pid>
      <joint_name>rudder_joint</joint_name>
      <joint_scale>0.01</joint_scale>
      <joint_type>position</joint_type>
      <joint_pid>2000 0 10</joint_pid>
    </plugin>

    <plugin name="main_sail_controller" filename="libLinkJointControllerPlugin.so">
      <input_topic>/cmd_vel2</input_topic>
      <link_name>__default__</link_name>
      <link_scale>0</link_scale>
      <link_type>velocity</link_type>
      <link_pid>1000 0 10</link_pid>
      <joint_name>main_sail_joint</joint_name>
      <joint_scale>0.01</joint_scale>
      <joint_type>limit</joint_type>
      <joint_pid>1000 0 10</joint_pid>
    </plugin>

    <plugin name="jib_sail_controller" filename="libLinkJointControllerPlugin.so">
      <input_topic>/cmd_vel2</input_topic>
      <link_name>__default__</link_name>
      <link_scale>0</link_scale>
      <link_type>velocity</link_type>
      <link_pid>1000 0 10</link_pid>
      <joint_name>jib_sail_joint</joint_name>
      <joint_scale>0.01</joint_scale>
      <joint_type>limit</joint_type>
      <joint_pid>1000 0 10</joint_pid>
    </plugin>

    <!-- <plugin name="wing_sail_controller" filename="libLinkJointControllerPlugin.so">
      <input_topic>/cmd_vel2</input_topic>
      <link_name>__default__</link_name>
      <link_scale>0</link_scale>
      <link_type>velocity</link_type>
      <link_pid>1000 0 10</link_pid>
      <joint_name>wing_sail_joint</joint_name>
      <joint_scale>0.01</joint_scale>
      <joint_type>position</joint_type>
      <joint_pid>1000 0 10</joint_pid>
    </plugin> -->

    <!-- <plugin name="trim_tab_controller" filename="libLinkJointControllerPlugin.so">
      <input_topic>/cmd_vel2</input_topic>
      <link_name>__default__</link_name>
      <link_scale>0</link_scale>
      <link_type>velocity</link_type>
      <link_pid>1000 0 10</link_pid>
      <joint_name>trim_tab_joint</joint_name>
      <joint_scale>0.01</joint_scale>
      <joint_type>position</joint_type>
      <joint_pid>2000 0 10</joint_pid>
    </plugin> -->

    <plugin name="hydrodynamics" filename="libHydrodynamicsPlugin.so">
      <!-- Wave Model -->
      <wave_model>ocean_waves</wave_model>

      <!-- Hydrodynamics -->
      <damping_on>true</damping_on>
      <viscous_drag_on>true</viscous_drag_on>
      <pressure_drag_on>true</pressure_drag_on>

      <!-- Linear and Angular Damping -->
      <cDampL1>1.0E-6</cDampL1>
      <cDampL2>1.0E-6</cDampL2>
      <cDampR1>1.0E-6</cDampR1>
      <cDampR2>1.0E-6</cDampR2>

      <!-- 'Pressure' Drag -->
      <!-- <cPDrag1>0</cPDrag1>
      <cPDrag2>10</cPDrag2>
      <fPDrag>0.4</fPDrag>
      <cSDrag1>0</cSDrag1>
      <cSDrag2>9</cSDrag2>
      <fSDrag>0.5</fSDrag>
      <vRDrag>1.0</vRDrag> -->
      <cPDrag1>0</cPDrag1>
      <cPDrag2>1</cPDrag2>
      <fPDrag>0.4</fPDrag>
      <cSDrag1>0</cSDrag1>
      <cSDrag2>1</cSDrag2>
      <fSDrag>0.4</fSDrag>
      <vRDrag>1.0</vRDrag>

      <!-- Markers -->
      <markers>
        <update_rate>30</update_rate>
        <water_patch>false</water_patch>
        <waterline>false</waterline>
        <underwater_surface>false</underwater_surface>
      </markers>
    </plugin>

    <plugin name="main_sail_liftdrag" filename="libSailPlugin.so">
      <a0>0.0</a0>
      <cla>6.2832</cla>
      <alpha_stall>0.1592</alpha_stall>
      <cla_stall>-0.7083</cla_stall>
      <cda>0.63662</cda>
      <area>1.81</area>
      <fluid_density>1.2</fluid_density>
      <forward>1 0 0</forward>
      <upward>0 1 0</upward>
      <cp>-0.30875 0 1.30625</cp>
      <link_name>main_sail_link</link_name>
      <radial_symmetry>true</radial_symmetry>
      <topic>lift_drag</topic>
    </plugin>

    <plugin name="jib_sail_liftdrag" filename="libSailPlugin.so">
      <a0>0.0</a0>
      <cla>6.2832</cla>
      <alpha_stall>0.1592</alpha_stall>
      <cla_stall>-0.7083</cla_stall>
      <cda>0.63662</cda>
      <area>1.43</area>
      <fluid_density>1.2</fluid_density>
      <forward>1 0 0</forward>
      <upward>0 1 0</upward>
      <cp>-0.605666667 0 1.20528</cp>
      <link_name>jib_sail_link</link_name>
      <radial_symmetry>true</radial_symmetry>
      <topic>lift_drag</topic>
    </plugin>

    <!-- <plugin name="wing_sail_liftdrag" filename="libSailPlugin.so">
      <a0>0.0</a0>
      <cla>6.2832</cla>
      <alpha_stall>0.1592</alpha_stall>
      <cla_stall>-0.7083</cla_stall>
      <cda>0.63662</cda>
      <area>2.0</area>
      <fluid_density>1.2</fluid_density>
      <forward>1 0 0</forward>
      <upward>0 1 0</upward>
      <cp>0 0 0</cp>
      <link_name>wing_sail_link</link_name>
      <radial_symmetry>true</radial_symmetry>
      <topic>lift_drag</topic>
    </plugin>

    <plugin name="trim_tab_liftdrag" filename="libSailPlugin.so">
      <a0>0.0</a0>
      <cla>6.2832</cla>
      <alpha_stall>0.1592</alpha_stall>
      <cla_stall>-0.7083</cla_stall>
      <cda>0.63662</cda>
      <area>0.5</area>
      <fluid_density>1.2</fluid_density>
      <forward>1 0 0</forward>
      <upward>0 1 0</upward>
      <cp>0 0 0</cp>
      <link_name>trim_tab_link</link_name>
      <radial_symmetry>true</radial_symmetry>
      <topic>lift_drag</topic>
    </plugin> -->

    <plugin name="keel_liftdrag" filename="libFoilPlugin.so">
      <a0>0.0</a0>
      <cla>6.2832</cla>
      <alpha_stall>0.1592</alpha_stall>
      <cla_stall>-0.7083</cla_stall>
      <cda>0.63662</cda>
      <area>0.17</area>
      <fluid_density>1000</fluid_density>
      <forward>1 0 0</forward>
      <upward>0 1 0</upward>
      <cp>0 0 0</cp>
      <link_name>keel_link</link_name>
      <radial_symmetry>true</radial_symmetry>
      <topic>lift_drag</topic>
    </plugin>

    <plugin name="rudder_liftdrag" filename="libFoilPlugin.so">
      <a0>0.0</a0>
      <cla>6.2832</cla>
      <alpha_stall>0.1592</alpha_stall>
      <cla_stall>-0.7083</cla_stall>
      <cda>0.63662</cda>
      <area>0.12</area>
      <fluid_density>1000</fluid_density>
      <forward>1 0 0</forward>
      <upward>0 1 0</upward>
      <cp>-0.06 0 -0.2</cp>
      <link_name>rudder_link</link_name>
      <radial_symmetry>true</radial_symmetry>
      <topic>lift_drag</topic>
    </plugin>

    <!-- Hull -->
    <link name="base_link">
      <visual name="hull_visual">
        <pose>0 0 0 0 0 0</pose>
        <geometry>
          <mesh>
            <uri>model://rs750/meshes/rs750_hull.stl</uri>
          </mesh>
        </geometry>
        <material>
          <script>
            <name>Gazebo/Red</name>
          </script>
        </material>
      </visual>

      <visual name="deck_visual">
        <pose>0 0 0 0 0 0</pose>
        <geometry>
          <mesh>
            <uri>model://rs750/meshes/rs750_deck.stl</uri>
          </mesh>
        </geometry>
        <material>
          <script>
            <name>Gazebo/Gray</name>
          </script>
        </material>
      </visual>

      <!-- <visual name="keel_fin_visual">
        <pose>-0.16255 -0.00512 -0.54053 0 0 0</pose>
        <geometry>
          <mesh>
            <uri>model://rs750/meshes/rs750_keel_fin.stl</uri>
          </mesh>
        </geometry>
        <material>
          <script>
            <name>Gazebo/Gray</name>
          </script>
        </material>
      </visual>

      <visual name="keel_bulb_visual">
        <pose>-0.26638 0.01038 -1.08674 0 0 0</pose>
        <geometry>
          <mesh>
            <uri>model://rs750/meshes/rs750_keel_bulb.stl</uri>
          </mesh>
        </geometry>
        <material>
          <script>
            <name>Gazebo/Gray</name>
          </script>
        </material>
      </visual> -->

      <!-- Rigging  -->
      <visual name="mast_visual">
        <pose>0 0 2.09 0 0 0</pose>
        <geometry>
          <mesh>
            <uri>model://rs750/meshes/rs750_mast.stl</uri>
          </mesh>
        </geometry>
        <material>
          <script>
            <name>Gazebo/Gray</name>
          </script>
        </material>
      </visual>

      <collision name="base_collision">
        <pose>0 0 0 0 0 0</pose>
        <geometry>
          <mesh>
            <uri>model://rs750/meshes/rs750_hull_collision_3.stl</uri>
          </mesh>
        </geometry>
      </collision>

      <!-- <collision name="keel_fin_collision">
       <pose>-0.16255 -0.00512 -0.54053 0 0 0</pose>
         <geometry>
          <mesh>
            <uri>model://rs750/meshes/rs750_keel_fin_collision_2.stl</uri>
          </mesh>
        </geometry>
      </collision> -->

      <inertial>
        <pose>-0.1 0 -0.75 0 0 0</pose>
        <mass>60</mass>
        <inertia>
          <ixx>10</ixx>
          <ixy>0</ixy>
          <iyy>50</iyy>
          <iyz>0</iyz>
          <izz>43</izz>
        </inertia>
      </inertial>

      <!-- Sensors -->
      <sensor name="mast_head_anemometer" type="anemometer">
        <pose>0 0 4.049375 0 0 0</pose>
        <always_on>true</always_on>
        <update_rate>50</update_rate>
        <topic>mast_head_anemometer</topic>
      </sensor>
      <visual name="mast_head_anemometer_visual">
        <pose>0 0 4.049375 0 0 0</pose>
        <geometry>
          <cylinder>
            <radius>0.025</radius>
            <length>0.025</length>
          </cylinder>
        </geometry>
        <material>
          <script>
            <name>Gazebo/Red</name>
          </script>
        </material>
      </visual>

      <sensor name="mast_base_anemometer" type="anemometer">
        <pose>0 0 0.130625 0 0 0</pose>
        <always_on>true</always_on>
        <update_rate>50</update_rate>
        <topic>mast_head_anemometer</topic>
      </sensor>
      <visual name="mast_base_anemometer_visual">
        <pose>0 0 0.130625 0 0 0</pose>
        <geometry>
          <cylinder>
            <radius>0.025</radius>
            <length>0.025</length>
          </cylinder>
        </geometry>
        <material>
          <script>
            <name>Gazebo/Red</name>
          </script>
        </material>
      </visual>

    </link>

    <!-- Keel -->
    <link name="keel_link">
      <pose>0 0 0 0 0 0</pose>

      <visual name="keel_fin_visual">
        <pose>-0.16255 -0.00512 -0.54053 0 0 0</pose>
        <geometry>
          <mesh>
            <uri>model://rs750/meshes/rs750_keel_fin.stl</uri>
          </mesh>
        </geometry>
        <material>
          <script>
            <name>Gazebo/Gray</name>
          </script>
        </material>
      </visual>

      <visual name="keel_bulb_visual">
        <pose>-0.26638 0.01038 -1.08674 0 0 0</pose>
        <geometry>
          <mesh>
            <uri>model://rs750/meshes/rs750_keel_bulb.stl</uri>
          </mesh>
        </geometry>
        <material>
          <script>
            <name>Gazebo/Gray</name>
          </script>
        </material>
      </visual>

      <collision name="keel_fin_collision">
       <pose>-0.16255 -0.00512 -0.54053 0 0 0</pose>
         <geometry>
          <mesh>
            <uri>model://rs750/meshes/rs750_keel_fin_collision_2.stl</uri>
          </mesh>
        </geometry>
      </collision>

      <inertial>
        <pose>0 0 0 0 0 0</pose>
        <mass>10.0</mass>
        <inertia>
          <ixx>1.6</ixx>
          <ixy>0</ixy>
          <iyy>1.6</iyy>
          <iyz>0</iyz>
          <izz>1.6</izz>
        </inertia>
      </inertial>
    </link>

    <joint type="revolute" name="keel_joint">
      <pose>0 0 0 0 0 0</pose>
      <child>keel_link</child>
      <parent>base_link</parent>
      <axis>
        <xyz>1 0 0</xyz>
        <initial_position>0</initial_position>
        <limit>
          <lower>-0.01</lower>
          <upper>0.01</upper>
        </limit>
      </axis>
      <sensor name="keel_force_torque" type="keel_torque">
        <always_on>true</always_on>
        <update_rate>30</update_rate>
        <visualize>true</visualize>
      </sensor>
    </joint>

    <!-- Rudder -->
    <link name="rudder_link">
      <pose>-1.2436 -0.00323 -0.0487 0 0 0</pose>

      <visual name="rudder_visual">
        <geometry>
          <mesh>
            <uri>model://rs750/meshes/rs750_rudder.stl</uri>
          </mesh>
        </geometry>
        <material>
          <script>
            <name>Gazebo/Gray</name>
          </script>
        </material>
      </visual>

      <collision name="rudder_collision">
        <geometry>
          <mesh>
            <uri>model://rs750/meshes/rs750_rudder_collision_3.stl</uri>
          </mesh>
        </geometry>
      </collision>

      <inertial>
        <pose>0 0 0 0 0 0</pose>
        <mass>0.1</mass>
        <inertia>
          <ixx>0.1</ixx>
          <ixy>0</ixy>
          <iyy>0.1</iyy>
          <iyz>0</iyz>
          <izz>0.1</izz>
        </inertia>
      </inertial>
    </link>

    <joint type="revolute" name="rudder_joint">
      <pose>0 0 0 0 0 0</pose>
      <child>rudder_link</child>
      <parent>base_link</parent>
      <axis>
        <xyz>0 0 1</xyz>
        <initial_position>0</initial_position>
        <limit>
          <lower>-0.7</lower>
          <upper>0.7</upper>
        </limit>
      </axis>
      <sensor name="rudder_force_torque" type="force_torque">
        <always_on>true</always_on>
        <update_rate>30</update_rate>
        <visualize>true</visualize>
      </sensor>
    </joint>

    <!-- Main Sail -->
    <link name="main_sail_link">
      <pose>-0.02625 0 0.291875 0 0 0</pose>

      <visual name="main_sail_visual">
        <geometry>
          <mesh>
            <uri>model://rs750/meshes/rs750_main_sail.stl</uri>
          </mesh>
        </geometry>
        <material>
          <script>
            <name>Gazebo/Gray</name>
          </script>
        </material>
      </visual>

      <visual name="main_boom_visual">
        <pose>-0.463125 0 -0.01125 0 0 0</pose>
        <geometry>
          <mesh>
            <uri>model://rs750/meshes/rs750_main_boom.stl</uri>
          </mesh>
        </geometry>
        <material>
          <script>
            <name>Gazebo/Gray</name>
          </script>
        </material>
      </visual>

      <collision name="main_sail_collision">
        <geometry>
          <mesh>
            <uri>model://rs750/meshes/rs750_main_sail.stl</uri>
          </mesh>
        </geometry>
      </collision>

      <inertial>
        <pose>0 0 0 0 0 0</pose>
        <mass>0.1</mass>
        <inertia>
          <ixx>0.1</ixx>
          <ixy>0</ixy>
          <iyy>0.1</iyy>
          <iyz>0</iyz>
          <izz>0.1</izz>
        </inertia>
      </inertial>

      <sensor name="main_sail_anemometer" type="anemometer">
        <pose>-0.30875 0 1.30625 0 0 0</pose>
        <always_on>true</always_on>
        <update_rate>50</update_rate>
        <topic>main_sail_anemometer</topic>
      </sensor>
      <visual name="main_sail_anemometer_visual">
        <pose>-0.30875 0 1.30625 0 0 0</pose>
        <geometry>
          <cylinder>
            <radius>0.025</radius>
            <length>0.025</length>
          </cylinder>
        </geometry>
        <material>
          <script>
            <name>Gazebo/Red</name>
          </script>
        </material>
      </visual>

    </link>

    <joint type="revolute" name="main_sail_joint">
      <pose>0 0 0 0 0 0</pose>
      <child>main_sail_link</child>
      <parent>base_link</parent>
      <axis>
        <xyz>0 0 1</xyz>
        <initial_position>0</initial_position>
        <limit>
          <lower>-1.7</lower>
          <upper>1.7</upper>
        </limit>
      </axis>
      <sensor name="main_sail_force_torque" type="force_torque">
        <always_on>true</always_on>
        <update_rate>30</update_rate>
        <visualize>true</visualize>
      </sensor>
    </joint>

    <!-- Jib Sail -->
    <link name="jib_sail_link">
      <pose>1.03125 0 0.235625 0 0 0</pose>

      <visual name="jib_sail_visual">
        <geometry>
          <mesh>
            <uri>model://rs750/meshes/rs750_jib_sail.stl</uri>
          </mesh>
        </geometry>
        <material>
          <script>
            <name>Gazebo/Gray</name>
          </script>
        </material>
      </visual>

      <visual name="jib_boom_visual">
        <pose>-0.463125 0 -0.01125 0 0 0</pose>
        <geometry>
          <mesh>
            <uri>model://rs750/meshes/rs750_jib_boom.stl</uri>
          </mesh>
        </geometry>
        <material>
          <script>
            <name>Gazebo/Gray</name>
          </script>
        </material>
      </visual>

      <collision name="jib_sail_collision">
        <geometry>
          <mesh>
            <uri>model://rs750/meshes/rs750_jib_sail.stl</uri>
          </mesh>
        </geometry>
      </collision>

      <inertial>
        <pose>0 0 0 0 0 0</pose>
        <mass>0.1</mass>
        <inertia>
          <ixx>0.1</ixx>
          <ixy>0</ixy>
          <iyy>0.1</iyy>
          <iyz>0</iyz>
          <izz>0.1</izz>
        </inertia>
      </inertial>

      <sensor name="jib_sail_anemometer" type="anemometer">
        <pose>-0.605666667 0 1.20528 0 0 0</pose>
        <always_on>true</always_on>
        <update_rate>50</update_rate>
        <topic>jib_sail_anemometer</topic>
      </sensor>
      <visual name="jib_sail_anemometer_visual">
        <pose>-0.605666667 0 1.20528 0 0 0</pose>
        <geometry>
          <cylinder>
            <radius>0.025</radius>
            <length>0.025</length>
          </cylinder>
        </geometry>
        <material>
          <script>
            <name>Gazebo/Red</name>
          </script>
        </material>
      </visual>

    </link>

    <joint type="revolute" name="jib_sail_joint">
      <pose>0 0 0 0 0 0</pose>
      <child>jib_sail_link</child>
      <parent>base_link</parent>
      <axis>
        <xyz>-0.271652766 0 0.962395332</xyz>
        <initial_position>0</initial_position>
        <limit>
          <lower>-1.7</lower>
          <upper>1.7</upper>
        </limit>
      </axis>
      <sensor name="jib_sail_force_torque" type="force_torque">
        <always_on>true</always_on>
        <update_rate>30</update_rate>
        <visualize>true</visualize>
      </sensor>
    </joint>

    <!-- Wing sail -->
    <!-- <link name="wing_sail_link">
      <pose>0 0 2.15 0 0 0</pose>
      <visual name="wing_sail_visual">
        <geometry>
          <box>
            <size>0.5 0.01 4</size>
          </box>
        </geometry>
        <material>
          <script>
            <name>Gazebo/Gray</name>
          </script>
        </material>
      </visual>
      <collision name="wing_sail_collision">
        <geometry>
          <box>
            <size>0.5 0.01 4</size>
          </box>
        </geometry>
      </collision>
      <visual name="trim_tab_support_visual">
        <pose>0 0 0 0 1.570796 0</pose>
        <geometry>
          <cylinder>
            <radius>0.01</radius>
            <length>2</length>
          </cylinder>
        </geometry>
        <material>
          <script>
            <name>Gazebo/Gray</name>
          </script>
        </material>
      </visual>
      <inertial>
        <pose>0 0 0 0 0 0</pose>
        <mass>1</mass>
        <inertia>
          <ixx>0.16</ixx>
          <ixy>0</ixy>
          <iyy>0.16</iyy>
          <iyz>0</iyz>
          <izz>0.16</izz>
        </inertia>
      </inertial>

      <sensor name="anemometer_sensor" type="anemometer">
        <pose>0 0 0 0 0 0</pose>
        <always_on>true</always_on>
        <update_rate>50</update_rate>
        <topic>anemometer</topic>
      </sensor>
      <visual name="anemometer_visual">
        <pose>0 0 0 0 0 0</pose>
        <geometry>
          <cylinder>
            <radius>0.025</radius>
            <length>0.025</length>
          </cylinder>
        </geometry>
        <material>
          <script>
            <name>Gazebo/Red</name>
          </script>
        </material>
      </visual>
    </link>

    <joint type="revolute" name="wing_sail_joint">
      <pose>0.2 0 0 0 0 0</pose>
      <child>wing_sail_link</child>
      <parent>base_link</parent>
      <axis>
        <xyz>0 0 1</xyz>
        <initial_position>0</initial_position>
        <dynamics>
          <damping>5</damping>
          <friction>1</friction>
        </dynamics>
      </axis>
      <sensor name="wing_sail_force_torque" type="force_torque">
        <always_on>true</always_on>
        <update_rate>30</update_rate>
        <visualize>true</visualize>
      </sensor>
    </joint> -->

    <!-- Trim tab -->
    <!-- <link name="trim_tab_link">
      <pose>-0.9 0 2.15 0 0 0</pose>

      <visual name="trim_tab_visual">
        <geometry>
          <box>
            <size>0.2 0.01 0.5</size>
          </box>
        </geometry>
        <material>
          <script>
            <name>Gazebo/Gray</name>
          </script>
        </material>
      </visual>

      <collision name="trim_tab_collision">
        <geometry>
          <box>
            <size>0.2 0.01 0.5</size>
          </box>
        </geometry>
      </collision>

      <inertial>
        <pose>0 0 0 0 0 0</pose>
        <mass>1</mass>
        <inertia>
          <ixx>0.16</ixx>
          <ixy>0</ixy>
          <iyy>0.16</iyy>
          <iyz>0</iyz>
          <izz>0.16</izz>
        </inertia>
      </inertial>

    </link>

    <joint type="revolute" name="trim_tab_joint">
      <pose>0.025 0 0 0 0 0</pose>
      <child>trim_tab_link</child>
      <parent>wing_sail_link</parent>
      <axis>
        <xyz>0 0 1</xyz>
        <initial_position>0</initial_position>
        <limit>
          <lower>-1.5</lower>
          <upper>1.5</upper>
        </limit>
      </axis>
      <sensor name="trim_tab_force_torque" type="force_torque">
        <always_on>true</always_on>
        <update_rate>30</update_rate>
        <visualize>true</visualize>
      </sensor>
    </joint> -->

  </model>
</sdf>
