<?xml version="1.0" ?>
<!--
  Copyright (C) 2019  Rhys Mainwaring

  This program is free software: you can redistribute it and/or modify
  it under the terms of the GNU General Public License as published by
  the Free Software Foundation, either version 3 of the License, or
  (at your option) any later version.

  This program is distributed in the hope that it will be useful,
  but WITHOUT ANY WARRANTY; without even the implied warranty of
  MERCHANTABILITY or FITNESS FOR A PARTICULAR PURPOSE.  See the
  GNU General Public License for more details.

  You should have received a copy of the GNU General Public License
  along with this program.  If not, see <https://www.gnu.org/licenses/>.
-->
<!-- 
  Specifications:

  L = 4.95m
  C = 0m
  +/- 2.475m

  Mass is calculated for steel. 4.95m x 0.01m x 0.01m is 3.81kg.
  Links are offset at 5.0m, 10.0m, etc.
  Joints must be offset -2.5m
-->
<sdf version="1.6">
  <model name="chain_long">        
    <static>false</static>    

    <include>      
      <pose>0 0 0 0 0 0</pose>
      <uri>model://chain_link_long</uri>
      <name>chain_link0</name>
    </include>

    <include>
      <pose>5.0 0 0 0 0 0</pose>
      <uri>model://chain_link_long</uri>
      <name>chain_link1</name>
    </include>


    <joint type="ball" name="chain_link_0_1_joint">
      <pose>-2.5 0 0 0 0 0</pose>
      <parent>chain_link0::base_link</parent>
      <child>chain_link1::base_link</child>
    </joint>

  </model>
</sdf>
