<?xml version='1.0'?>
<!--
  Copyright (C) 2019  Rhys Mainwaring

  This program is free software: you can redistribute it and/or modify
  it under the terms of the GNU General Public License as published by
  the Free Software Foundation, either version 3 of the License, or
  (at your option) any later version.

  This program is distributed in the hope that it will be useful,
  but WITHOUT ANY WARRANTY; without even the implied warranty of
  MERCHANTABILITY or FITNESS FOR A PARTICULAR PURPOSE.  See the
  GNU General Public License for more details.

  You should have received a copy of the GNU General Public License
  along with this program.  If not, see <https://www.gnu.org/licenses/>.
-->
<sdf version='1.6'>
  <model name='wakeboard_boat'>
    <pose>0 0 0 0 0 0</pose>
    <static>false</static>

    <plugin name="link_joint_controller" filename="libLinkJointControllerPlugin.so">
      <input_topic>/cmd_vel</input_topic>
      <link_name>thruster_link</link_name>
      <link_scale>40</link_scale>
      <link_type>velocity</link_type>
      <link_pid>1000 0 10</link_pid>
      <joint_name>thruster_joint</joint_name>
      <joint_scale>0.8</joint_scale>
      <joint_type>position</joint_type>
      <joint_pid>1000 0 10</joint_pid>
    </plugin>

    <plugin name="hydrodynamics" filename="libHydrodynamicsPlugin.so">
      <!-- Wave Model -->
      <wave_model>ocean_waves</wave_model>

      <!-- Hydrodynamics -->
      <damping_on>true</damping_on>
      <viscous_drag_on>true</viscous_drag_on>
      <pressure_drag_on>true</pressure_drag_on>

      <!-- Linear and Angular Damping -->
      <cDampL1>1.0E-6</cDampL1>
      <cDampL2>1.0E-6</cDampL2>
      <cDampR1>1.0E-6</cDampR1>
      <cDampR2>1.0E-6</cDampR2>

      <!-- 'Pressure' Drag -->
      <cPDrag1>1.0E+2</cPDrag1>
      <cPDrag2>1.0E+2</cPDrag2>
      <fPDrag>0.4</fPDrag>
      <cSDrag1>1.0E+2</cSDrag1>
      <cSDrag2>1.0E+2</cSDrag2>
      <fSDrag>0.4</fSDrag>
      <vRDrag>1.0</vRDrag>

      <!-- Markers -->
      <markers>
        <update_rate>30</update_rate>
        <water_patch>false</water_patch>
        <waterline>false</waterline>
        <underwater_surface>false</underwater_surface>
      </markers>
    </plugin>

    <!-- Hull -->
    <link name="base_link">
      <visual name="base_visual">
        <geometry>
          <mesh>
            <uri>model://wakeboard_boat/meshes/wakeboard_boat.stl</uri>
          </mesh>
        </geometry>
        <material>
          <script>
            <name>Gazebo/Gray</name>
          </script>
        </material>
      </visual>
      <collision name="base_collision">
        <geometry>
          <mesh>
            <uri>model://wakeboard_boat/meshes/wakeboard_boat_collision.stl</uri>
          </mesh>
        </geometry>
      </collision>
      <inertial>
        <pose>0 0 -0.3 0 0 0</pose>
        <mass>1000</mass>
        <inertia>
          <ixx>332</ixx>
          <ixy>0</ixy>
          <iyy>2255</iyy>
          <iyz>0</iyz>
          <izz>2446</izz>
        </inertia>
      </inertial>

      <!-- Camera -->
      <visual name="cam_visual">
        <pose>0.62 0 0.7 0 0 0</pose>
        <geometry>
          <box>
            <size>0.1 0.1 0.1</size>
          </box>
        </geometry>
        <material>
          <script>
            <uri>__default__</uri>
            <name>Gazebo/Red</name>
          </script>
        </material>
      </visual>

      <sensor type="camera" name="cam1">
        <pose>0.62 0 0.7 0 0 0</pose>
        <always_on>1</always_on>>
        <update_rate>0</update_rate>
        <camera name="cam1">
          <horizontal_fov>1.5</horizontal_fov>
          <image>
            <width>800</width>
            <height>800</height>
            <format>R8G8B8</format>
          </image>
          <clip>
            <near>0.02</near>
            <far>300</far>
          </clip>
        </camera>
        <plugin name="camera_controller" filename="libgazebo_ros_camera.so">
          <alwaysOn>true</alwaysOn>
          <updateRate>0.0</updateRate>
          <cameraName>rrbot/camera1</cameraName>
          <imageTopicName>image_raw</imageTopicName>
          <cameraInfoTopicName>camera_info</cameraInfoTopicName>
          <frameName>camera_link_optical</frameName>
          <hackBaseline>0.07</hackBaseline>
          <distortionK1>0.0</distortionK1>
          <distortionK2>0.0</distortionK2>
          <distortionK3>0.0</distortionK3>
          <distortionT1>0.0</distortionT1>
          <distortionT2>0.0</distortionT2>
        </plugin>
      </sensor>

    </link>

    <!-- Thruster -->
    <link name="thruster_link">
      <pose>-1.4 0 -0.8 0 0.1 0</pose>
      <visual name="thruster_visual">
        <geometry>
          <box>
            <size>0.2 0.2 0.2</size>
          </box>
        </geometry>
        <material>
          <script>
            <name>Gazebo/Black</name>
          </script>
        </material>
      </visual>
      <collision name="thruster_collision">
        <geometry>
          <box>
            <size>0.2 0.2 0.2</size>
          </box>
        </geometry>
      </collision>
      <inertial>
        <pose>0 0 0 0 0 0</pose>
        <mass>61</mass>
        <inertia>
          <ixx>0.41</ixx>
          <ixy>0</ixy>
          <iyy>0.41</iyy>
          <iyz>0</iyz>
          <izz>0.41</izz>
        </inertia>
      </inertial>
    </link>

    <joint type="revolute" name="thruster_joint">
      <pose>0 0 0 0 0 0</pose>
      <child>thruster_link</child>
      <parent>base_link</parent>
      <axis>
        <xyz>0 0 1</xyz>
        <limit>
          <lower>-0.8</lower>
          <upper>0.8</upper>
        </limit>
      </axis>
    </joint>

  </model>
</sdf>
