<?xml version="1.0" ?>
<!--
  Copyright (C) 2019  Rhys Mainwaring

  This program is free software: you can redistribute it and/or modify
  it under the terms of the GNU General Public License as published by
  the Free Software Foundation, either version 3 of the License, or
  (at your option) any later version.

  This program is distributed in the hope that it will be useful,
  but WITHOUT ANY WARRANTY; without even the implied warranty of
  MERCHANTABILITY or FITNESS FOR A PARTICULAR PURPOSE.  See the
  GNU General Public License for more details.

  You should have received a copy of the GNU General Public License
  along with this program.  If not, see <https://www.gnu.org/licenses/>.
-->
<!-- 
  Specifications:

  L = 0.45m
  C = 0m
  +/- 0.225m

  Mass is calculated for steel. 0.45m x 0.01m x 0.01m is 0.3465kg.
  Links are offset at 0.5m, 1.0m, 1.5m, 2.0m, etc.
  Joints must be offset -0.25m
-->
<sdf version="1.6">
  <model name="chain">        
    <static>false</static>
        
    <include>      
      <pose>0 0 0 0 0 0</pose>
      <uri>model://chain_link</uri>
      <name>chain_link0</name>
    </include>

    <include>
      <pose>0.5 0 0 0 0 0</pose>
      <uri>model://chain_link</uri>
      <name>chain_link1</name>
    </include>

    <include>
      <pose>1.0 0 0 0 0 0</pose>
      <uri>model://chain_link</uri>
      <name>chain_link2</name>
    </include>

    <include>
      <pose>1.5 0 0 0 0 0</pose>
      <uri>model://chain_link</uri>
      <name>chain_link3</name>
    </include>

    <include>
      <pose>2.0 0 0 0 0 0</pose>
      <uri>model://chain_link</uri>
      <name>chain_link4</name>
    </include>

    <include>
      <pose>2.5 0 0 0 0 0</pose>
      <uri>model://chain_link</uri>
      <name>chain_link5</name>
    </include>

    <include>
      <pose>3.0 0 0 0 0 0</pose>
      <uri>model://chain_link</uri>
      <name>chain_link6</name>
    </include>

    <include>
      <pose>3.5 0 0 0 0 0</pose>
      <uri>model://chain_link</uri>
      <name>chain_link7</name>
    </include>

    <include>
      <pose>4.0 0 0 0 0 0</pose>
      <uri>model://chain_link</uri>
      <name>chain_link8</name>
    </include>

    <include>
      <pose>4.5 0 0 0 0 0</pose>
      <uri>model://chain_link</uri>
      <name>chain_link9</name>
    </include>

    <include>
      <pose>5.0 0 0 0 0 0</pose>
      <uri>model://chain_link</uri>
      <name>chain_link10</name>
    </include>

    <include>
      <pose>5.5 0 0 0 0 0</pose>
      <uri>model://chain_link</uri>
      <name>chain_link11</name>
    </include>

    <include>
      <pose>6.0 0 0 0 0 0</pose>
      <uri>model://chain_link</uri>
      <name>chain_link12</name>
    </include>

    <include>
      <pose>6.5 0 0 0 0 0</pose>
      <uri>model://chain_link</uri>
      <name>chain_link13</name>
    </include>

    <include>
      <pose>7.0 0 0 0 0 0</pose>
      <uri>model://chain_link</uri>
      <name>chain_link14</name>
    </include>

    <include>
      <pose>7.5 0 0 0 0 0</pose>
      <uri>model://chain_link</uri>
      <name>chain_link15</name>
    </include>

    <include>
      <pose>8.0 0 0 0 0 0</pose>
      <uri>model://chain_link</uri>
      <name>chain_link16</name>
    </include>

    <include>
      <pose>8.5 0 0 0 0 0</pose>
      <uri>model://chain_link</uri>
      <name>chain_link17</name>
    </include>

    <include>
      <pose>9.0 0 0 0 0 0</pose>
      <uri>model://chain_link</uri>
      <name>chain_link18</name>
    </include>

    <include>
      <pose>9.5 0 0 0 0 0</pose>
      <uri>model://chain_link</uri>
      <name>chain_link19</name>
    </include>

    <joint type="ball" name="chain_link_0_1_joint">
      <pose>-0.25 0 0 0 0 0</pose>
      <parent>chain_link0::base_link</parent>
      <child>chain_link1::base_link</child>
    </joint>

    <joint type="ball" name="chain_link_1_2_joint">
      <pose>-0.25 0 0 0 0 0</pose>
      <parent>chain_link1::base_link</parent>
      <child>chain_link2::base_link</child>
    </joint>

    <joint type="ball" name="chain_link_2_3_joint">
      <pose>-0.25 0 0 0 0 0</pose>
      <parent>chain_link2::base_link</parent>
      <child>chain_link3::base_link</child>
    </joint>

    <joint type="ball" name="chain_link_3_4_joint">
      <pose>-0.25 0 0 0 0 0</pose>
      <parent>chain_link3::base_link</parent>
      <child>chain_link4::base_link</child>
    </joint>

    <joint type="ball" name="chain_link_4_5_joint">
      <pose>-0.25 0 0 0 0 0</pose>
      <parent>chain_link4::base_link</parent>
      <child>chain_link5::base_link</child>
    </joint>

    <joint type="ball" name="chain_link_5_6_joint">
      <pose>-0.25 0 0 0 0 0</pose>
      <parent>chain_link5::base_link</parent>
      <child>chain_link6::base_link</child>
    </joint>

    <joint type="ball" name="chain_link_6_7_joint">
      <pose>-0.25 0 0 0 0 0</pose>
      <parent>chain_link6::base_link</parent>
      <child>chain_link7::base_link</child>
    </joint>

    <joint type="ball" name="chain_link_7_8_joint">
      <pose>-0.25 0 0 0 0 0</pose>
      <parent>chain_link7::base_link</parent>
      <child>chain_link8::base_link</child>
    </joint>

    <joint type="ball" name="chain_link_8_9_joint">
      <pose>-0.25 0 0 0 0 0</pose>
      <parent>chain_link8::base_link</parent>
      <child>chain_link9::base_link</child>
    </joint>

    <joint type="ball" name="chain_link_9_10_joint">
      <pose>-0.25 0 0 0 0 0</pose>
      <parent>chain_link9::base_link</parent>
      <child>chain_link10::base_link</child>
    </joint>

    <joint type="ball" name="chain_link_10_11_joint">
      <pose>-0.25 0 0 0 0 0</pose>
      <parent>chain_link10::base_link</parent>
      <child>chain_link11::base_link</child>
    </joint>

    <joint type="ball" name="chain_link_11_12_joint">
      <pose>-0.25 0 0 0 0 0</pose>
      <parent>chain_link11::base_link</parent>
      <child>chain_link12::base_link</child>
    </joint>

    <joint type="ball" name="chain_link_12_13_joint">
      <pose>-0.25 0 0 0 0 0</pose>
      <parent>chain_link12::base_link</parent>
      <child>chain_link13::base_link</child>
    </joint>

    <joint type="ball" name="chain_link_13_14_joint">
      <pose>-0.25 0 0 0 0 0</pose>
      <parent>chain_link13::base_link</parent>
      <child>chain_link14::base_link</child>
    </joint>

    <joint type="ball" name="chain_link_14_15_joint">
      <pose>-0.25 0 0 0 0 0</pose>
      <parent>chain_link14::base_link</parent>
      <child>chain_link15::base_link</child>
    </joint>

    <joint type="ball" name="chain_link_15_16_joint">
      <pose>-0.25 0 0 0 0 0</pose>
      <parent>chain_link15::base_link</parent>
      <child>chain_link16::base_link</child>
    </joint>

    <joint type="ball" name="chain_link_16_17_joint">
      <pose>-0.25 0 0 0 0 0</pose>
      <parent>chain_link16::base_link</parent>
      <child>chain_link17::base_link</child>
    </joint>

    <joint type="ball" name="chain_link_17_18_joint">
      <pose>-0.25 0 0 0 0 0</pose>
      <parent>chain_link17::base_link</parent>
      <child>chain_link18::base_link</child>
    </joint>

    <joint type="ball" name="chain_link_18_19_joint">
      <pose>-0.25 0 0 0 0 0</pose>
      <parent>chain_link18::base_link</parent>
      <child>chain_link19::base_link</child>
    </joint>

  </model>
</sdf>
